 * Serving Flask app "claves" (lazy loading)
 * Environment: production
   WARNING: This is a development server. Do not use it in a production deployment.
   Use a production WSGI server instead.
 * Debug mode: off
 * Running on https://0.0.0.0:4000/ (Press CTRL+C to quit)
127.0.0.1 - - [31/May/2024 19:57:56] "[37mGET / HTTP/1.1[0m" 200 -
127.0.0.1 - - [31/May/2024 20:00:24] "[33mPOST /login/v2 HTTP/1.1[0m" 404 -
 * Serving Flask app "claves" (lazy loading)
 * Environment: production
   WARNING: This is a development server. Do not use it in a production deployment.
   Use a production WSGI server instead.
 * Debug mode: off
Traceback (most recent call last):
  File "claves.py", line 103, in <module>
    app.run(host='0.0.0.0', port=4000, ssl_context='adhoc')
  File "/home/devasc/.local/lib/python3.8/site-packages/flask/app.py", line 990, in run
    run_simple(host, port, self, **options)
  File "/home/devasc/.local/lib/python3.8/site-packages/werkzeug/serving.py", line 1052, in run_simple
    inner()
  File "/home/devasc/.local/lib/python3.8/site-packages/werkzeug/serving.py", line 996, in inner
    srv = make_server(
  File "/home/devasc/.local/lib/python3.8/site-packages/werkzeug/serving.py", line 847, in make_server
    return ThreadedWSGIServer(
  File "/home/devasc/.local/lib/python3.8/site-packages/werkzeug/serving.py", line 740, in __init__
    HTTPServer.__init__(self, server_address, handler)
  File "/usr/lib/python3.8/socketserver.py", line 452, in __init__
    self.server_bind()
  File "/usr/lib/python3.8/http/server.py", line 138, in server_bind
    socketserver.TCPServer.server_bind(self)
  File "/usr/lib/python3.8/socketserver.py", line 466, in server_bind
    self.socket.bind(self.server_address)
OSError: [Errno 98] Address already in use
127.0.0.1 - - [31/May/2024 20:01:40] "[37mGET / HTTP/1.1[0m" 200 -
 * Serving Flask app "claves" (lazy loading)
 * Environment: production
   WARNING: This is a development server. Do not use it in a production deployment.
   Use a production WSGI server instead.
 * Debug mode: off
 * Running on https://0.0.0.0:4000/ (Press CTRL+C to quit)
127.0.0.1 - - [31/May/2024 20:07:43] "[37mGET / HTTP/1.1[0m" 200 -
[2024-05-31 20:07:57,583] ERROR in app: Exception on /login/v2 [POST]
Traceback (most recent call last):
  File "/home/devasc/.local/lib/python3.8/site-packages/flask/app.py", line 2447, in wsgi_app
    response = self.full_dispatch_request()
  File "/home/devasc/.local/lib/python3.8/site-packages/flask/app.py", line 1952, in full_dispatch_request
    rv = self.handle_user_exception(e)
  File "/home/devasc/.local/lib/python3.8/site-packages/flask/app.py", line 1821, in handle_user_exception
    reraise(exc_type, exc_value, tb)
  File "/home/devasc/.local/lib/python3.8/site-packages/flask/_compat.py", line 39, in reraise
    raise value
  File "/home/devasc/.local/lib/python3.8/site-packages/flask/app.py", line 1950, in full_dispatch_request
    rv = self.dispatch_request()
  File "/home/devasc/.local/lib/python3.8/site-packages/flask/app.py", line 1936, in dispatch_request
    return self.view_functions[rule.endpoint](**req.view_args)
  File "claves.py", line 93, in login_v2
    if verify_hash(request.form['username'], request.form['password']):
  File "claves.py", line 82, in verify_hash
    c.execute(query)
sqlite3.OperationalError: no such table: USER_HASH
127.0.0.1 - - [31/May/2024 20:07:57] "[35m[1mPOST /login/v2 HTTP/1.1[0m" 500 -
[2024-05-31 20:08:52,925] ERROR in app: Exception on /login/v2 [POST]
Traceback (most recent call last):
  File "/home/devasc/.local/lib/python3.8/site-packages/flask/app.py", line 2447, in wsgi_app
    response = self.full_dispatch_request()
  File "/home/devasc/.local/lib/python3.8/site-packages/flask/app.py", line 1952, in full_dispatch_request
    rv = self.handle_user_exception(e)
  File "/home/devasc/.local/lib/python3.8/site-packages/flask/app.py", line 1821, in handle_user_exception
    reraise(exc_type, exc_value, tb)
  File "/home/devasc/.local/lib/python3.8/site-packages/flask/_compat.py", line 39, in reraise
    raise value
  File "/home/devasc/.local/lib/python3.8/site-packages/flask/app.py", line 1950, in full_dispatch_request
    rv = self.dispatch_request()
  File "/home/devasc/.local/lib/python3.8/site-packages/flask/app.py", line 1936, in dispatch_request
    return self.view_functions[rule.endpoint](**req.view_args)
  File "claves.py", line 93, in login_v2
    if verify_hash(request.form['username'], request.form['password']):
  File "claves.py", line 82, in verify_hash
    c.execute(query)
sqlite3.OperationalError: no such table: USER_HASH
127.0.0.1 - - [31/May/2024 20:08:52] "[35m[1mPOST /login/v2 HTTP/1.1[0m" 500 -
 * Serving Flask app "claves" (lazy loading)
 * Environment: production
   WARNING: This is a development server. Do not use it in a production deployment.
   Use a production WSGI server instead.
 * Debug mode: off
 * Running on https://0.0.0.0:4000/ (Press CTRL+C to quit)
127.0.0.1 - - [31/May/2024 20:09:29] "[37mGET / HTTP/1.1[0m" 200 -
127.0.0.1 - - [31/May/2024 20:11:56] "[37mPOST /signup/v2 HTTP/1.1[0m" 200 -
127.0.0.1 - - [31/May/2024 20:14:43] "[37mPOST /signup/v2 HTTP/1.1[0m" 200 -
127.0.0.1 - - [31/May/2024 20:16:20] "[37mPOST /login/v2 HTTP/1.1[0m" 200 -
127.0.0.1 - - [31/May/2024 20:18:25] "[37mPOST /login/v2 HTTP/1.1[0m" 200 -
